__rethrow_casa_exceptions = True
h_init()
try:
    hifa_restoredata (vis=['uid___A002_Xd69abb_Xbf53', 'uid___A002_Xd66bb8_X55fc', 'uid___A002_Xd69abb_Xab5f', 'uid___A002_Xd4b9e4_X8e1a', 'uid___A002_Xd69abb_X1158c', 'uid___A002_Xd69abb_X400b', 'uid___A002_Xd61e68_X44ea', 'uid___A002_Xd659d4_X4531', 'uid___A002_Xd3c7c2_X664a', 'uid___A002_Xd4b9e4_X7fa8'], session=['session_8', 'session_5', 'session_7', 'session_2', 'session_9', 'session_6', 'session_3', 'session_4', 'session_1', 'session_2'], ocorr_mode='ca')
finally:
    h_save()
